Workbook

Sheet Sheet1
A1: 标题 | B1: sku | C1: url | D1: min_price | E1: enabled | F1: 原价
A2: XRK-300Mbps Router 4G LTE Mobile Hotspot with SIM Card Slot | B2: CPF101-E8 | C2: https://www.takealot.com/xrk-300mbps-router-4g-lte-mobile-hotspot-with-sim-card-slot/PLID100772788 | D2: 865 | E2: 0 | G2: 1=监控
A3: XRK-CPE 4G Router with SIM Card Slot WiFi 6 4 LAN Ports 300Mbps | B3: WR950-E+DC | C3: https://www.takealot.com/xrk-cpe-4g-router-with-sim-card-slot-wifi-6-4-lan-ports-300mbps/PLID100773431 | D3: 760 | E3: 0 | G3: 0=关闭跳过
A4: Portable WiFi 4G LTE SIM Card Router 300Mbps High Speed Portable Router | B4: M32 - E Blue | C4: https://www.takealot.com/portable-wifi-4g-lte-sim-card-router-300mbps-high-speed-portable/PLID100467205 | D4: 413 | E4: 0
A5: Teeth Gem Set European and American Hip Hop Style DIY Teeth Diamond Set | B5: teeth001 | C5: https://www.takealot.com/teeth-gem-set-european-and-american-hip-hop-style-diy-teeth-diam/PLID100491409 | D5: 227 | E5: 0
A6: Diamond Tooth Grill Set European and American Hip-Hop Style DIY | B6: teeth002 | C6: https://www.takealot.com/diamond-tooth-grill-set-european-and-american-hip-hop-style-diy/PLID100562278 | D6: 225 | E6: 0
A7: XRK-4G LTE Mobile Hotspot 300Mbps Wireless Router with SIM Card Slot | B7: CPF919-E | C7: https://www.takealot.com/xrk-4g-lte-mobile-hotspot-300mbps-wireless-router-with-sim-card/PLID100940190 | D7: 550 | E7: 0 | F7: 899
A8: XRK-4G Router Portable WiFi Wireless Outdoor Network 300Mbps 2100mAh | B8: M1-E+TX | C8: https://www.takealot.com/xrk-4g-router-portable-wifi-wireless-outdoor-network-300mbps-210/PLID100939238 | D8: 560 | E8: 0 | F8: 799
A9: XRK-5G Router Supports SIM Card WiFi 6 Dual Band 2.4G & 5G | B9: NR180-E | C9: https://www.takealot.com/xrk-5g-router-supports-sim-card-wifi-6-dual-band-2-4g-5g/PLID100926942 | D9: 2100 | E9: 0 | F9: 2399
A10: XRK-WiFi6 4G Router Portable WiFi Wireless Outdoor Network 300Mbps - Blue, Black | B10: MF967B-E-Blue | C10: https://www.takealot.com/xrk-wifi6-4g-router-portable-wifi-wireless-outdoor-network-300mb/PLID100926242?colour_variant=Blue%2C+Black | D10: 510 | E10: 0 | F10: 749
A11: XRK-WiFi6 4G Router Portable WiFi Wireless Outdoor Network 300Mbps - Orange, Black | B11: MF967B-E-Orange | C11: https://www.takealot.com/xrk-wifi6-4g-router-portable-wifi-wireless-outdoor-network-300mb/PLID100926242?colour_variant=Orange%2C+Black | D11: 510 | E11: 0 | F11: 749
A12: XRK-5G SIM Card 600Mbps WiFi6 Dual Band Router with WAN/LAN Ports | B12: NR200-E | C12: https://www.takealot.com/xrk-5g-sim-card-600mbps-wifi6-dual-band-router-with-wan-lan-port/PLID100831133 | D12: 2300 | E12: 0 | F12: 2399
A13: XRK Portable Home Wireless Electric Green Juicer 450ML 2 Cups | B13: SY-Juicer-38Knife-Green | C13: https://www.takealot.com/xrk-portable-home-wireless-electric-green-juicer-450ml-2-cups/PLID100826535 | D13: 430 | E13: 0 | F13: 599
A14: XRK Portable Home Wireless Electric White Juicer 450ML 2 Cups | B14: SY-Juicer-38Knife-White | C14: https://www.takealot.com/xrk-portable-home-wireless-electric-white-juicer-450ml-2-cups/PLID100770976 | D14: 430 | E14: 0 | F14: 599
A15: XRK Portable Home Wireless Electric Pink Juicer 450ML 2 Cups | B15: SY-Juicer-38Knife-Pink | C15: https://www.takealot.com/xrk-portable-home-wireless-electric-pink-juicer-450ml-2-cups/PLID100662728 | D15: 430 | E15: 0 | F15: 599
A16: XRK-WiFi6 5G Portable WiFi Router Dual-Band 600Mbps Wireless Router | B16: M3A-E | C16: https://www.takealot.com/xrk-wifi6-5g-portable-wifi-router-dual-band-600mbps-wireless-rou/PLID100789861 | D16: 2150 | E16: 0 | F16: 2399 | G16: 已停产
A17: XRK-WIFI6 Portable Router 300Mbps 4G Wireless SIM Card Portable Mobile WiFi | B17: MF967P-E+cp | C17: https://www.takealot.com/xrk-wifi6-portable-router-300mbps-4g-wireless-sim-card-portable/PLID100789855 | D17: 510 | E17: 0 | F17: 739
A18: XRK-5G Portable Pocket WiFi Color Screen Dual-Band Wireless Router 600Mbps | B18: M2A-E | C18: https://www.takealot.com/xrk-5g-portable-pocket-wifi-color-screen-dual-band-wireless-rout/PLID100773558 | D18: 2100 | E18: 0 | F18: 2399
A19: XRK-5G Router CPE Router Supports SIM Card and LAN Port WiFi 6 Dual Band | B19: M55-E | C19: https://www.takealot.com/xrk-5g-router-cpe-router-supports-sim-card-and-lan-port-wifi-6-d/PLID100748039 | D19: 2100 | E19: 0 | F19: 2399
A20: XRK-4G SIM Card Portable WiFi 6 Router with 45 RJ Network Ports | B20: Q52-E | C20: https://www.takealot.com/xrk-4g-sim-card-portable-wifi-6-router-with-45-rj-network-ports/PLID100748037 | D20: 710 | E20: 0 | F20: 959
A21: XRK-5G Router CPE Router Supports SIM Card WiFi 6 Dual Band 2.4G & 5G | B21: NR800-E | C21: https://www.takealot.com/xrk-5g-router-cpe-router-supports-sim-card-wifi-6-dual-band-2-4g/PLID100744776 | D21: 2600 | E21: 0 | F21: 2799
A22: XRK-4G LTE SIM Card Router CPE for Home and Office with 2 LAN Ports | B22: 210B-E | C22: https://www.takealot.com/xrk-4g-lte-sim-card-router-cpe-for-home-and-office-with-2-lan-po/PLID100744044 | D22: 790 | E22: 0 | F22: 999
A23: XRK - Tilt-Head Doll Resin Desktop Ornament, Irregular Decoration | B23: Tilted Head Doll001 | C23: https://www.takealot.com/xrk-tilt-head-doll-resin-desktop-ornament-irregular-decoration/PLID100744408 | D23: 475 | E23: 0 | F23: 499
A24: XRK-Three-color mode desk lamp for use at the bedside or in the office | B24: JCT057B | C24: https://www.takealot.com/xrk-three-color-mode-desk-lamp-for-use-at-the-bedside-or-in-the/PLID100689541 | D24: 900 | E24: 0 | F24: 999
A25: XRK-WiFi 6 Wireless Portable Router 4G 300Mbps Dual Band Shared Hotspot - Blue | B25: M10Pro-E-Blue | C25: https://www.takealot.com/xrk-wifi-6-wireless-portable-router-4g-300mbps-dual-band-shared/PLID100686073?colour_variant=Blue | D25: 490 | E25: 0 | F25: 659
A26: XRK-WiFi 6 Wireless Portable Router 4G 300Mbps Dual Band Shared Hotspot - White | B26: M10Pro-E-White | C26: https://www.takealot.com/xrk-wifi-6-wireless-portable-router-4g-300mbps-dual-band-shared/PLID100686073?colour_variant=White | D26: 490 | E26: 0 | F26: 659
A27: XRK-WIFI6 Wireless Portable Router 600Mbps 5G Network Supports 32 Users | B27: M8A-E | C27: https://www.takealot.com/xrk-wifi6-wireless-portable-router-600mbps-5g-network-supports-3/PLID100681209 | D27: 2100 | E27: 0 | F27: 2399
A28: Bathroom Faucet Brass Faucet Outdoor Faucet Garden Faucet Bathroom | B28: faucet001 | C28: https://www.takealot.com/bathroom-faucet-brass-faucet-outdoor-faucet-garden-faucet-bathro/PLID100625782 | D28: 410 | E28: 0 | F28: 499
... A33: 150cm Medium and Large Dog Leash, Soft Cotton Handle, Alloy Buckle - Pink | B33: TF051-PINK | C33: https://www.takealot.com/150cm-medium-and-large-dog-leash-soft-cotton-handle-alloy-buckle/PLID100537186 | D33: 450 | E33: 0 | F33: 529
A34: Camping Sleeping Pad, light Camping Mat , Built-in Foot Pump Inflatable | B34: cqcd001 | C34: https://www.takealot.com/camping-sleeping-pad-light-camping-mat-built-in-foot-pump-inflat/PLID100477361 | D34: 660 | E34: 0
A35: Curling Wand Straight Hair Comb Multifunctional Styling Comb Portable | B35: hair115 | C35: https://www.takealot.com/curling-wand-straight-hair-comb-multifunctional-styling-comb-por/PLID100477143 | D35: 480 | E35: 0 | F35: 619
A36: XRK-Curling Wand Straight Hair Comb Multifunctional Styling Comb Portable | B36: hairNEW115 | C36: https://www.takealot.com/xrk-curling-wand-straight-hair-comb-multifunctional-styling-comb/PLID100748659 | D36: 450 | E36: 0 | F36: 616
A37: 4G Portable WiFi Mobile Router 300Mbps High Speed Supports 10 Devices | B37: MF967 - 5 Orange | C37: https://www.takealot.com/4g-portable-wifi-mobile-router-300mbps-high-speed-supports-10-de/PLID100468554 | D37: 485 | E37: 0 | F37: 729
A38: Stronger Signal Portable Color Screen 600Mbps Wireless WiFi6 Router 5G | B38: M2D - E | C38: https://www.takealot.com/stronger-signal-portable-color-screen-600mbps-wireless-wifi6-rou/PLID100468552 | D38: 2200 | E38: 1
A39: 4G Wireless Portable Mobile WiFi Router 300Mbps High-Speed Hotspot - Blue | B39: M33 - E Blue | C39: https://www.takealot.com/4g-wireless-portable-mobile-wifi-router-300mbps-high-speed-hotsp/PLID100468485 | D39: 400 | E39: 0 | F39: 629
A40: Wireless High-Speed 4G WiFi Router Portable MiFi | B40: M28 - E White | C40: https://www.takealot.com/wireless-high-speed-4g-wifi-router-portable-mifi/PLID100467412 | D40: 400 | E40: 0
A41: Portable MIFI LTE Router Mobile WiFi Wireless Power Bank | B41: M27 - E | C41: https://www.takealot.com/portable-mifi-lte-router-mobile-wifi-wireless-power-bank/PLID100467007 | D41: 560 | E41: 0 | F41: 799
A42: Windshield Cover for Ice and Snow Universal Fit for Car SUV Truck | B42: S-c190-k107 | C42: https://www.takealot.com/windshield-cover-for-ice-and-snow-universal-fit-for-car-suv-truc/PLID100417221 | D42: 400 | E42: 0
A43: XRK-Windshield Cover for Ice and Snow Universal Fit for Car SUV Truck - small | B43: Windshield Cover-S | C43: https://www.takealot.com/xrk-windshield-cover-for-ice-and-snow-universal-fit-for-car-suv/PLID100681745?colour_variant=small | D43: 400 | E43: 0
A44: XRK-Windshield Cover for Ice and Snow Universal Fit for Car SUV Truck - big | B44: Windshield Cover-L | C44: https://www.takealot.com/xrk-windshield-cover-for-ice-and-snow-universal-fit-for-car-suv/PLID100681745?colour_variant=big | D44: 450 | E44: 0
...

Sheet Sheet2
A1: SKU | B1: TSIN | C1: FOB价 | D1: 尾程配送费 | E1: VAT税率 | F1: 类目佣金 | G1: 前台价格 | H1: 头程总成本 | I1: 头程物流费rmb | J1: 南非关税rmb | K1: 进口vat税 | L1: 重量 | M1: 采购成本rmb | N1: 产品利润rmb | O1: 申报价值（美金）
A2: CPF101-E8 | B2: 102443856 | C2: =ROUND((H2+N2+M2)*2.54,2) -> 705.64 | D2: 80 | E2: 0.15 | F2: 0.1 | G2: =ROUND((C2+D2)/(1-F2*(1+E2)-5%),0) -> 941 | H2: =I2+J2+K2 -> 65.812 | I2: =L2*79+10 -> 62.14 | J2: =O2*7.2*0.3 -> 2.16 | K2: =(O2*1.1*7.2+J2)*0.15 -> 1.512 | L2: 0.66 | M2: 182 | N2: 30 | O2: 1
A3: WR950-E+DC | B3: 102445504 | C3: =ROUND((H3+N3+M3)*2.54,2) -> 609.12 | D3: 80 | E3: 0.15 | F3: 0.1 | G3: =ROUND((C3+D3)/(1-F3*(1+E3)-5%),0) -> 825 | H3: =I3+J3+K3 -> 65.812 | I3: =L3*79+10 -> 62.14 | J3: =O3*7.2*0.3 -> 2.16 | K3: =(O3*1.1*7.2+J3)*0.15 -> 1.512 | L3: 0.66 | M3: 144 | N3: 30 | O3: 1
A4: M32 - E Blue | B4: 102078544 | C4: =ROUND((H4+N4+M4)*2.54,2) -> 328.45 | D4: 80 | E4: 0.15 | F4: 0.1 | G4: =ROUND((C4+D4)/(1-F4*(1+E4)-5%),0) -> 489 | H4: =I4+J4+K4 -> 26.312 | I4: =L4*79+10 -> 22.64 | J4: =O4*7.2*0.3 -> 2.16 | K4: =(O4*1.1*7.2+J4)*0.15 -> 1.512 | L4: 0.16 | M4: 73 | N4: 30 | O4: 1
A5: teeth001 | B5: 102117796 | C5: =ROUND((H5+N5+M5)*2.54,2) -> 129.11 | D5: 80 | E5: 0.15 | F5: 0.1 | G5: =ROUND((C5+D5)/(1-F5*(1+E5)-5%),0) -> 250 | H5: =I5+J5+K5 -> 16.832 | I5: =L5*79+10 -> 13.16 | J5: =O5*7.2*0.3 -> 2.16 | K5: =(O5*1.1*7.2+J5)*0.15 -> 1.512 | L5: 0.04 | M5: 19 | N5: 15 | O5: 1
A6: teeth002 | B6: 102200523 | C6: =ROUND((H6+N6+M6)*2.54,2) -> 138.21 | D6: 80 | E6: 0.15 | F6: 0.1 | G6: =ROUND((C6+D6)/(1-F6*(1+E6)-5%),0) -> 261 | H6: =I6+J6+K6 -> 18.412 | I6: =L6*79+10 -> 14.74 | J6: =O6*7.2*0.3 -> 2.16 | K6: =(O6*1.1*7.2+J6)*0.15 -> 1.512 | L6: 0.06 | M6: 21 | N6: 15 | O6: 1
A7: CPF919-E | B7: 102646828 | C7: =ROUND((H7+N7+M7)*2.54,2) -> 442.9 | D7: 80 | E7: 0.15 | F7: 0.1 | G7: =ROUND((C7+D7)/(1-F7*(1+E7)-5%),0) -> 626 | H7: =I7+J7+K7 -> 37.372 | I7: =L7*79+10 -> 33.7 | J7: =O7*7.2*0.3 -> 2.16 | K7: =(O7*1.1*7.2+J7)*0.15 -> 1.512 | L7: 0.3 | M7: 107 | N7: 30 | O7: 1
A8: M1-E+TX | B8: 102645475 | C8: =ROUND((H8+N8+M8)*2.54,2) -> 459.47 | D8: 80 | E8: 0.15 | F8: 0.1 | G8: =ROUND((C8+D8)/(1-F8*(1+E8)-5%),0) -> 646 | H8: =I8+J8+K8 -> 27.892 | I8: =L8*79+10 -> 24.22 | J8: =O8*7.2*0.3 -> 2.16 | K8: =(O8*1.1*7.2+J8)*0.15 -> 1.512 | L8: 0.18 | M8: 123 | N8: 30 | O8: 1
A9: NR180-E | B9: 102628280 | C9: =ROUND((H9+N9+M9)*2.54,2) -> 1629.97 | D9: 80 | E9: 0.15 | F9: 0.1 | G9: =ROUND((C9+D9)/(1-F9*(1+E9)-5%),0) -> 2048 | H9: =I9+J9+K9 -> 88.722 | I9: =L9*79+10 -> 85.05 | J9: =O9*7.2*0.3 -> 2.16 | K9: =(O9*1.1*7.2+J9)*0.15 -> 1.512 | L9: 0.95 | M9: 523 | N9: 30 | O9: 1
A10: MF967B-E-Blue | B10: 102627230 | C10: =ROUND((H10+N10+M10)*2.54,2) -> 409.07 | D10: 80 | E10: 0.15 | F10: 0.1 | G10: =ROUND((C10+D10)/(1-F10*(1+E10)-5%),0) -> 586 | H10: =I10+J10+K10 -> 31.052 | I10: =L10*79+10 -> 27.38 | J10: =O10*7.2*0.3 -> 2.16 | K10: =(O10*1.1*7.2+J10)*0.15 -> 1.512 | L10: 0.22 | M10: 100 | N10: 30 | O10: 1
A11: MF967B-E-Orange | B11: 102627231 | C11: =ROUND((H11+N11+M11)*2.54,2) -> 409.07 | D11: 80 | E11: 0.15 | F11: 0.1 | G11: =ROUND((C11+D11)/(1-F11*(1+E11)-5%),0) -> 586 | H11: =I11+J11+K11 -> 31.052 | I11: =L11*79+10 -> 27.38 | J11: =O11*7.2*0.3 -> 2.16 | K11: =(O11*1.1*7.2+J11)*0.15 -> 1.512 | L11: 0.22 | M11: 100 | N11: 30 | O11: 1
A12: NR200-E | B12: 102521734 | C12: =ROUND((H12+N12+M12)*2.54,2) -> 251.39 | D12: 80 | E12: 0.15 | F12: 0.1 | G12: =ROUND((C12+D12)/(1-F12*(1+E12)-5%),0) -> 397 | H12: =I12+J12+K12 -> 68.972 | I12: =L12*79+10 -> 65.3 | J12: =O12*7.2*0.3 -> 2.16 | K12: =(O12*1.1*7.2+J12)*0.15 -> 1.512 | L12: 0.7 | N12: 30 | O12: 1
A13: SY-Juicer-38Knife-Green | B13: 102514447 | C13: =ROUND((H13+N13+M13)*2.54,2) -> 411.92 | D13: 80 | E13: 0.15 | F13: 0.1 | G13: =ROUND((C13+D13)/(1-F13*(1+E13)-5%),0) -> 589 | H13: =I13+J13+K13 -> 132.172 | I13: =L13*79+10 -> 128.5 | J13: =O13*7.2*0.3 -> 2.16 | K13: =(O13*1.1*7.2+J13)*0.15 -> 1.512 | L13: 1.5 | N13: 30 | O13: 1
A14: SY-Juicer-38Knife-White | B14: 102441514 | C14: =ROUND((H14+N14+M14)*2.54,2) -> 411.92 | D14: 80 | E14: 0.15 | F14: 0.1 | G14: =ROUND((C14+D14)/(1-F14*(1+E14)-5%),0) -> 589 | H14: =I14+J14+K14 -> 132.172 | I14: =L14*79+10 -> 128.5 | J14: =O14*7.2*0.3 -> 2.16 | K14: =(O14*1.1*7.2+J14)*0.15 -> 1.512 | L14: 1.5 | N14: 30 | O14: 1
A15: SY-Juicer-38Knife-Pink | B15: 102313681 | C15: =ROUND((H15+N15+M15)*2.54,2) -> 411.92 | D15: 80 | E15: 0.15 | F15: 0.1 | G15: =ROUND((C15+D15)/(1-F15*(1+E15)-5%),0) -> 589 | H15: =I15+J15+K15 -> 132.172 | I15: =L15*79+10 -> 128.5 | J15: =O15*7.2*0.3 -> 2.16 | K15: =(O15*1.1*7.2+J15)*0.15 -> 1.512 | L15: 1.5 | N15: 30 | O15: 1
A16: M3A-E | B16: 102466820 | C16: =ROUND((H16+N16+M16)*2.54,2) -> 151.06 | D16: 80 | E16: 0.15 | F16: 0.1 | G16: =ROUND((C16+D16)/(1-F16*(1+E16)-5%),0) -> 277 | H16: =I16+J16+K16 -> 29.472 | I16: =L16*79+10 -> 25.8 | J16: =O16*7.2*0.3 -> 2.16 | K16: =(O16*1.1*7.2+J16)*0.15 -> 1.512 | L16: 0.2 | N16: 30 | O16: 1
A17: MF967P-E+cp | B17: 102466814 | C17: =ROUND((H17+N17+M17)*2.54,2) -> 143.03 | D17: 80 | E17: 0.15 | F17: 0.1 | G17: =ROUND((C17+D17)/(1-F17*(1+E17)-5%),0) -> 267 | H17: =I17+J17+K17 -> 26.312 | I17: =L17*79+10 -> 22.64 | J17: =O17*7.2*0.3 -> 2.16 | K17: =(O17*1.1*7.2+J17)*0.15 -> 1.512 | L17: 0.16 | N17: 30 | O17: 1
A18: M2A-E | B18: 102445665 | C18: =ROUND((H18+N18+M18)*2.54,2) -> 181.16 | D18: 80 | E18: 0.15 | F18: 0.1 | G18: =ROUND((C18+D18)/(1-F18*(1+E18)-5%),0) -> 313 | H18: =I18+J18+K18 -> 41.322 | I18: =L18*79+10 -> 37.65 | J18: =O18*7.2*0.3 -> 2.16 | K18: =(O18*1.1*7.2+J18)*0.15 -> 1.512 | L18: 0.35 | N18: 30 | O18: 1
A19: M55-E | B19: 102407642 | C19: =ROUND((H19+N19+M19)*2.54,2) -> 243.36 | D19: 80 | E19: 0.15 | F19: 0.1 | G19: =ROUND((C19+D19)/(1-F19*(1+E19)-5%),0) -> 387 | H19: =I19+J19+K19 -> 65.812 | I19: =L19*79+10 -> 62.14 | J19: =O19*7.2*0.3 -> 2.16 | K19: =(O19*1.1*7.2+J19)*0.15 -> 1.512 | L19: 0.66 | N19: 30 | O19: 1
A20: Q52-E | B20: 102407640 | C20: =ROUND((H20+N20+M20)*2.54,2) -> 191.19 | D20: 80 | E20: 0.15 | F20: 0.1 | G20: =ROUND((C20+D20)/(1-F20*(1+E20)-5%),0) -> 325 | H20: =I20+J20+K20 -> 45.272 | I20: =L20*79+10 -> 41.6 | J20: =O20*7.2*0.3 -> 2.16 | K20: =(O20*1.1*7.2+J20)*0.15 -> 1.512 | L20: 0.4 | N20: 30 | O20: 1
A21: NR800-E | B21: 102403598 | C21: =ROUND((H21+N21+M21)*2.54,2) -> 110.93 | D21: 80 | E21: 0.15 | F21: 0.1 | G21: =ROUND((C21+D21)/(1-F21*(1+E21)-5%),0) -> 229 | H21: =I21+J21+K21 -> 13.672 | I21: =L21*79+10 -> 10 | J21: =O21*7.2*0.3 -> 2.16 | K21: =(O21*1.1*7.2+J21)*0.15 -> 1.512 | N21: 30 | O21: 1
A22: 210B-E | B22: 102402320 | C22: =ROUND((H22+N22+M22)*2.54,2) -> 579.81 | D22: 80 | E22: 0.15 | F22: 0.1 | G22: =ROUND((C22+D22)/(1-F22*(1+E22)-5%),0) -> 790 | H22: =I22+J22+K22 -> 45.272 | I22: =L22*79+10 -> 41.6 | J22: =O22*7.2*0.3 -> 2.16 | K22: =(O22*1.1*7.2+J22)*0.15 -> 1.512 | L22: 0.4 | M22: 153 | N22: 30 | O22: 1
A23: Tilted Head Doll001 | B23: 102402988 | C23: =ROUND((H23+N23+M23)*2.54,2) -> 110.93 | D23: 80 | E23: 0.15 | F23: 0.1 | G23: =ROUND((C23+D23)/(1-F23*(1+E23)-5%),0) -> 229 | H23: =I23+J23+K23 -> 13.672 | I23: =L23*79+10 -> 10 | J23: =O23*7.2*0.3 -> 2.16 | K23: =(O23*1.1*7.2+J23)*0.15 -> 1.512 | N23: 30 | O23: 1
A24: JCT057B | B24: 102348144 | C24: =ROUND((H24+N24+M24)*2.54,2) -> 110.93 | D24: 80 | E24: 0.15 | F24: 0.1 | G24: =ROUND((C24+D24)/(1-F24*(1+E24)-5%),0) -> 229 | H24: =I24+J24+K24 -> 13.672 | I24: =L24*79+10 -> 10 | J24: =O24*7.2*0.3 -> 2.16 | K24: =(O24*1.1*7.2+J24)*0.15 -> 1.512 | N24: 30 | O24: 1
A25: M10Pro-E-Blue | B25: 102341879 | C25: =ROUND((H25+N25+M25)*2.54,2) -> 151.06 | D25: 80 | E25: 0.15 | F25: 0.1 | G25: =ROUND((C25+D25)/(1-F25*(1+E25)-5%),0) -> 277 | H25: =I25+J25+K25 -> 29.472 | I25: =L25*79+10 -> 25.8 | J25: =O25*7.2*0.3 -> 2.16 | K25: =(O25*1.1*7.2+J25)*0.15 -> 1.512 | L25: 0.2 | N25: 30 | O25: 1
A26: M10Pro-E-White | B26: 102341881 | C26: =ROUND((H26+N26+M26)*2.54,2) -> 151.06 | D26: 80 | E26: 0.15 | F26: 0.1 | G26: =ROUND((C26+D26)/(1-F26*(1+E26)-5%),0) -> 277 | H26: =I26+J26+K26 -> 29.472 | I26: =L26*79+10 -> 25.8 | J26: =O26*7.2*0.3 -> 2.16 | K26: =(O26*1.1*7.2+J26)*0.15 -> 1.512 | L26: 0.2 | N26: 30 | O26: 1
A27: M8A-E | B27: 102333879 | C27: =ROUND((H27+N27+M27)*2.54,2) -> 181.16 | D27: 80 | E27: 0.15 | F27: 0.1 | G27: =ROUND((C27+D27)/(1-F27*(1+E27)-5%),0) -> 313 | H27: =I27+J27+K27 -> 41.322 | I27: =L27*79+10 -> 37.65 | J27: =O27*7.2*0.3 -> 2.16 | K27: =(O27*1.1*7.2+J27)*0.15 -> 1.512 | L27: 0.35 | N27: 30 | O27: 1
A28: faucet001 | B28: 102275586 | C28: =ROUND((H28+N28+M28)*2.54,2) -> 110.93 | D28: 80 | E28: 0.15 | F28: 0.1 | G28: =ROUND((C28+D28)/(1-F28*(1+E28)-5%),0) -> 229 | H28: =I28+J28+K28 -> 13.672 | I28: =L28*79+10 -> 10 | J28: =O28*7.2*0.3 -> 2.16 | K28: =(O28*1.1*7.2+J28)*0.15 -> 1.512 | N28: 30 | O28: 1
A29: M31 - E White | B29: 102260736 | C29: =ROUND((H29+N29+M29)*2.54,2) -> 143.03 | D29: 80 | E29: 0.15 | F29: 0.1 | G29: =ROUND((C29+D29)/(1-F29*(1+E29)-5%),0) -> 267 | H29: =I29+J29+K29 -> 26.312 | I29: =L29*79+10 -> 22.64 | J29: =O29*7.2*0.3 -> 2.16 | K29: =(O29*1.1*7.2+J29)*0.15 -> 1.512 | L29: 0.16 | N29: 30 | O29: 1
A30: Q30 - E White | B30: 102260659 | C30: =ROUND((H30+N30+M30)*2.54,2) -> 171.12 | D30: 80 | E30: 0.15 | F30: 0.1 | G30: =ROUND((C30+D30)/(1-F30*(1+E30)-5%),0) -> 301 | H30: =I30+J30+K30 -> 37.372 | I30: =L30*79+10 -> 33.7 | J30: =O30*7.2*0.3 -> 2.16 | K30: =(O30*1.1*7.2+J30)*0.15 -> 1.512 | L30: 0.3 | N30: 30 | O30: 1
A31: M34 - E White | B31: 102260604 | C31: =ROUND((H31+N31+M31)*2.54,2) -> 157.08 | D31: 80 | E31: 0.15 | F31: 0.1 | G31: =ROUND((C31+D31)/(1-F31*(1+E31)-5%),0) -> 284 | H31: =I31+J31+K31 -> 31.842 | I31: =L31*79+10 -> 28.17 | J31: =O31*7.2*0.3 -> 2.16 | K31: =(O31*1.1*7.2+J31)*0.15 -> 1.512 | L31: 0.23 | N31: 30 | O31: 1
A32: M33 - E White | B32: 102260155 | C32: =ROUND((H32+N32+M32)*2.54,2) -> 143.03 | D32: 80 | E32: 0.15 | F32: 0.1 | G32: =ROUND((C32+D32)/(1-F32*(1+E32)-5%),0) -> 267 | H32: =I32+J32+K32 -> 26.312 | I32: =L32*79+10 -> 22.64 | J32: =O32*7.2*0.3 -> 2.16 | K32: =(O32*1.1*7.2+J32)*0.15 -> 1.512 | L32: 0.16 | N32: 30 | O32: 1
A33: TF051-PINK | B33: 102170905 | C33: =ROUND((H33+N33+M33)*2.54,2) -> 110.93 | D33: 80 | E33: 0.15 | F33: 0.1 | G33: =ROUND((C33+D33)/(1-F33*(1+E33)-5%),0) -> 229 | H33: =I33+J33+K33 -> 13.672 | I33: =L33*79+10 -> 10 | J33: =O33*7.2*0.3 -> 2.16 | K33: =(O33*1.1*7.2+J33)*0.15 -> 1.512 | N33: 30 | O33: 1
A34: cqcd001 | B34: 102103370 | C34: =ROUND((H34+N34+M34)*2.54,2) -> 110.93 | D34: 80 | E34: 0.15 | F34: 0.1 | G34: =ROUND((C34+D34)/(1-F34*(1+E34)-5%),0) -> 229 | H34: =I34+J34+K34 -> 13.672 | I34: =L34*79+10 -> 10 | J34: =O34*7.2*0.3 -> 2.16 | K34: =(O34*1.1*7.2+J34)*0.15 -> 1.512 | N34: 30 | O34: 1
A35: hair115 | B35: 102103098 | C35: =ROUND((H35+N35+M35)*2.54,2) -> 191.19 | D35: 80 | E35: 0.15 | F35: 0.1 | G35: =ROUND((C35+D35)/(1-F35*(1+E35)-5%),0) -> 325 | H35: =I35+J35+K35 -> 45.272 | I35: =L35*79+10 -> 41.6 | J35: =O35*7.2*0.3 -> 2.16 | K35: =(O35*1.1*7.2+J35)*0.15 -> 1.512 | L35: 0.4 | N35: 30 | O35: 1
A36: hairNEW115 | B36: 102408847 | C36: =ROUND((H36+N36+M36)*2.54,2) -> 191.19 | D36: 80 | E36: 0.15 | F36: 0.1 | G36: =ROUND((C36+D36)/(1-F36*(1+E36)-5%),0) -> 325 | H36: =I36+J36+K36 -> 45.272 | I36: =L36*79+10 -> 41.6 | J36: =O36*7.2*0.3 -> 2.16 | K36: =(O36*1.1*7.2+J36)*0.15 -> 1.512 | L36: 0.4 | N36: 30 | O36: 1
A37: MF967 - 5 Orange | B37: 102081354 | C37: =ROUND((H37+N37+M37)*2.54,2) -> 143.03 | D37: 80 | E37: 0.15 | F37: 0.1 | G37: =ROUND((C37+D37)/(1-F37*(1+E37)-5%),0) -> 267 | H37: =I37+J37+K37 -> 26.312 | I37: =L37*79+10 -> 22.64 | J37: =O37*7.2*0.3 -> 2.16 | K37: =(O37*1.1*7.2+J37)*0.15 -> 1.512 | L37: 0.16 | N37: 30 | O37: 1
A38: M2D - E | B38: 102081352 | C38: =ROUND((H38+N38+M38)*2.54,2) -> 181.16 | D38: 80 | E38: 0.15 | F38: 0.1 | G38: =ROUND((C38+D38)/(1-F38*(1+E38)-5%),0) -> 313 | H38: =I38+J38+K38 -> 41.322 | I38: =L38*79+10 -> 37.65 | J38: =O38*7.2*0.3 -> 2.16 | K38: =(O38*1.1*7.2+J38)*0.15 -> 1.512 | L38: 0.35 | N38: 30 | O38: 1
A39: M33 - E Blue | B39: 102081276 | C39: =ROUND((H39+N39+M39)*2.54,2) -> 143.03 | D39: 80 | E39: 0.15 | F39: 0.1 | G39: =ROUND((C39+D39)/(1-F39*(1+E39)-5%),0) -> 267 | H39: =I39+J39+K39 -> 26.312 | I39: =L39*79+10 -> 22.64 | J39: =O39*7.2*0.3 -> 2.16 | K39: =(O39*1.1*7.2+J39)*0.15 -> 1.512 | L39: 0.16 | N39: 30 | O39: 1
A40: M28 - E White | B40: 102078927 | C40: =ROUND((H40+N40+M40)*2.54,2) -> 143.03 | D40: 80 | E40: 0.15 | F40: 0.1 | G40: =ROUND((C40+D40)/(1-F40*(1+E40)-5%),0) -> 267 | H40: =I40+J40+K40 -> 26.312 | I40: =L40*79+10 -> 22.64 | J40: =O40*7.2*0.3 -> 2.16 | K40: =(O40*1.1*7.2+J40)*0.15 -> 1.512 | L40: 0.16 | N40: 30 | O40: 1
...
